<?xml version="1.0" ?>
<robot name="test_robot">
    <link name="base_link">
        <inertial>
            <mass value="1.0"/>
            <inertia ixx="0.010416666666666666" iyy="0.010416666666666666" izz="0.010416666666666666" ixy="0.0" ixz="0.0" iyz="0.0"/>
            <origin xyz="0 0 0" rpy="0 0 0"/>
        </inertial>
        <visual>
            <origin xyz="0 0 0" rpy="0 0 0"/>
            <geometry>
                <box size="0.25 0.25 0.25"/>
            </geometry>
            <material name="gray">
                <color rgba="0.5 0.5 0.5 1"/>
            </material>
        </visual>
    </link>
    <joint name="sph_joint_x_1" type="revolute">
        <parent link="base_link"/>
        <child link="sph_link_x_1"/>
        <origin xyz="0 0 0.125" rpy="0 0 0"/>
        <axis xyz="1 0 0"/>
        <limit lower="-3.14" upper="3.14" effort="10" velocity="1"/>
    </joint>
    <link name="sph_link_x_1">
        <inertial>
            <mass value="0.001"/>
            <inertia ixx="4.000000000000001e-06" iyy="4.000000000000001e-06" izz="4.000000000000001e-06" ixy="0.0" ixz="0.0" iyz="0.0"/>
            <origin xyz="0 0 0" rpy="0 0 0"/>
        </inertial>
        <visual>
            <origin xyz="0 0 0" rpy="0 0 0"/>
            <geometry>
                <sphere radius="0.1"/>
            </geometry>
            <material name="limegreen">
                <color rgba="0.19607843137254902 0.803921568627451 0.19607843137254902 1.0"/>
            </material>
        </visual>
    </link>
    <joint name="sph_joint_y_1" type="revolute">
        <parent link="sph_link_x_1"/>
        <child link="sph_link_y_1"/>
        <origin xyz="0 0 0" rpy="0 0 0"/>
        <axis xyz="0 1 0"/>
        <limit lower="-3.14" upper="3.14" effort="10" velocity="1"/>
    </joint>
    <link name="sph_link_y_1">
        <inertial>
            <mass value="0.001"/>
            <inertia ixx="4.000000000000001e-06" iyy="4.000000000000001e-06" izz="4.000000000000001e-06" ixy="0.0" ixz="0.0" iyz="0.0"/>
            <origin xyz="0 0 0" rpy="0 0 0"/>
        </inertial>
        <visual>
            <origin xyz="0 0 0" rpy="0 0 0"/>
            <geometry>
                <sphere radius="0.1"/>
            </geometry>
            <material name="limegreen">
                <color rgba="0.19607843137254902 0.803921568627451 0.19607843137254902 1.0"/>
            </material>
        </visual>
    </link>
    <joint name="sph_joint_z_1" type="revolute">
        <parent link="sph_link_y_1"/>
        <child link="sph_link_z_1"/>
        <origin xyz="0 0 0" rpy="0 0 0"/>
        <axis xyz="0 0 1"/>
        <limit lower="-3.14" upper="3.14" effort="10" velocity="1"/>
    </joint>
    <link name="sph_link_z_1">
        <inertial>
            <mass value="0.001"/>
            <inertia ixx="4.000000000000001e-06" iyy="4.000000000000001e-06" izz="4.000000000000001e-06" ixy="0.0" ixz="0.0" iyz="0.0"/>
            <origin xyz="0 0 0" rpy="0 0 0"/>
        </inertial>
        <visual>
            <origin xyz="0 0 0" rpy="0 0 0"/>
            <geometry>
                <sphere radius="0.1"/>
            </geometry>
            <material name="limegreen">
                <color rgba="0.19607843137254902 0.803921568627451 0.19607843137254902 1.0"/>
            </material>
        </visual>
    </link>
    <joint name="joint0" type="fixed">
        <parent link="sph_link_z_1"/>
        <child link="link0"/>
        <origin xyz="0 0 0" rpy="0 0 0"/>
    </joint>
    <link name="link0">
        <inertial>
            <mass value="1.0"/>
            <inertia ixx="0.047499999999999994" iyy="0.047499999999999994" izz="0.0012500000000000002" ixy="0.0" ixz="0.0" iyz="0.0"/>
            <origin xyz="0 0 0.375" rpy="0 0 0"/>
        </inertial>
        <visual>
            <origin xyz="0 0 0.375" rpy="0 0 0"/>
            <geometry>
                <cylinder length="0.75" radius="0.05"/>
            </geometry>
            <material name="limegreen">
                <color rgba="0.19607843137254902 0.803921568627451 0.19607843137254902 1.0"/>
            </material>
        </visual>
        <collision>
            <origin xyz="0 0 0.375" rpy="0 0 0"/>
            <geometry>
                <cylinder length="0.75" radius="0.05"/>
            </geometry>
        </collision>
    </link>
    <joint name="joint1" type="prismatic">
        <parent link="link0"/>
        <child link="link1"/>
        <origin xyz="0 0 0.061" rpy="0 0 0"/>
        <axis xyz="0 0 1"/>
        <limit lower="0" upper="0.7" effort="10" velocity="1"/>
    </joint>
    <link name="link1">
        <inertial>
            <mass value="1.0"/>
            <inertia ixx="0.04275174999999999" iyy="0.04275174999999999" izz="0.0012500000000000002" ixy="0.0" ixz="0.0" iyz="0.0"/>
            <origin xyz="0 0 0.3555" rpy="0 0 0"/>
        </inertial>
        <visual>
            <origin xyz="0 0 0.3555" rpy="0 0 0"/>
            <geometry>
                <cylinder length="0.711" radius="0.05"/>
            </geometry>
            <material name="fuchsia">
                <color rgba="1.0 0.0 1.0 1.0"/>
            </material>
        </visual>
        <collision>
            <origin xyz="0 0 0.3555" rpy="0 0 0"/>
            <geometry>
                <cylinder length="0.711" radius="0.05"/>
            </geometry>
        </collision>
    </link>
    <joint name="sph_joint_x_2" type="revolute">
        <parent link="link1"/>
        <child link="sph_link_x_2"/>
        <origin xyz="0 0 0.711" rpy="0 0 0"/>
        <axis xyz="1 0 0"/>
        <limit lower="-3.14" upper="3.14" effort="10" velocity="1"/>
    </joint>
    <link name="sph_link_x_2">
        <inertial>
            <mass value="0.001"/>
            <inertia ixx="4.000000000000001e-06" iyy="4.000000000000001e-06" izz="4.000000000000001e-06" ixy="0.0" ixz="0.0" iyz="0.0"/>
            <origin xyz="0 0 0" rpy="0 0 0"/>
        </inertial>
        <visual>
            <origin xyz="0 0 0" rpy="0 0 0"/>
            <geometry>
                <sphere radius="0.1"/>
            </geometry>
            <material name="olivedrab">
                <color rgba="0.4196078431372549 0.5568627450980392 0.13725490196078433 1.0"/>
            </material>
        </visual>
    </link>
    <joint name="sph_joint_y_2" type="revolute">
        <parent link="sph_link_x_2"/>
        <child link="sph_link_y_2"/>
        <origin xyz="0 0 0" rpy="0 0 0"/>
        <axis xyz="0 1 0"/>
        <limit lower="-3.14" upper="3.14" effort="10" velocity="1"/>
    </joint>
    <link name="sph_link_y_2">
        <inertial>
            <mass value="0.001"/>
            <inertia ixx="4.000000000000001e-06" iyy="4.000000000000001e-06" izz="4.000000000000001e-06" ixy="0.0" ixz="0.0" iyz="0.0"/>
            <origin xyz="0 0 0" rpy="0 0 0"/>
        </inertial>
        <visual>
            <origin xyz="0 0 0" rpy="0 0 0"/>
            <geometry>
                <sphere radius="0.1"/>
            </geometry>
            <material name="olivedrab">
                <color rgba="0.4196078431372549 0.5568627450980392 0.13725490196078433 1.0"/>
            </material>
        </visual>
    </link>
    <joint name="sph_joint_z_2" type="revolute">
        <parent link="sph_link_y_2"/>
        <child link="sph_link_z_2"/>
        <origin xyz="0 0 0" rpy="0 0 0"/>
        <axis xyz="0 0 1"/>
        <limit lower="-3.14" upper="3.14" effort="10" velocity="1"/>
    </joint>
    <link name="sph_link_z_2">
        <inertial>
            <mass value="0.001"/>
            <inertia ixx="4.000000000000001e-06" iyy="4.000000000000001e-06" izz="4.000000000000001e-06" ixy="0.0" ixz="0.0" iyz="0.0"/>
            <origin xyz="0 0 0" rpy="0 0 0"/>
        </inertial>
        <visual>
            <origin xyz="0 0 0" rpy="0 0 0"/>
            <geometry>
                <sphere radius="0.1"/>
            </geometry>
            <material name="olivedrab">
                <color rgba="0.4196078431372549 0.5568627450980392 0.13725490196078433 1.0"/>
            </material>
        </visual>
    </link>
    <joint name="joint2" type="fixed">
        <parent link="sph_link_z_2"/>
        <child link="link2"/>
        <origin xyz="0 0 0" rpy="0 0 0"/>
    </joint>
    <link name="link2">
        <inertial>
            <mass value="1.0"/>
            <inertia ixx="0.021458333333333333" iyy="0.021458333333333333" izz="0.0012500000000000002" ixy="0.0" ixz="0.0" iyz="0.0"/>
            <origin xyz="0 0 0.25" rpy="0 0 0"/>
        </inertial>
        <visual>
            <origin xyz="0 0 0.25" rpy="0 0 0"/>
            <geometry>
                <cylinder length="0.5" radius="0.05"/>
            </geometry>
            <material name="olivedrab">
                <color rgba="0.4196078431372549 0.5568627450980392 0.13725490196078433 1.0"/>
            </material>
        </visual>
        <collision>
            <origin xyz="0 0 0.25" rpy="0 0 0"/>
            <geometry>
                <cylinder length="0.5" radius="0.05"/>
            </geometry>
        </collision>
    </link>
    <joint name="joint3" type="prismatic">
        <parent link="link2"/>
        <child link="link3"/>
        <origin xyz="0 0 0.061" rpy="0 0 0"/>
        <axis xyz="0 0 1"/>
        <limit lower="0" upper="0.45" effort="10" velocity="1"/>
    </joint>
    <link name="link3">
        <inertial>
            <mass value="1.0"/>
            <inertia ixx="0.018335083333333335" iyy="0.018335083333333335" izz="0.0012500000000000002" ixy="0.0" ixz="0.0" iyz="0.0"/>
            <origin xyz="0 0 0.2305" rpy="0 0 0"/>
        </inertial>
        <visual>
            <origin xyz="0 0 0.2305" rpy="0 0 0"/>
            <geometry>
                <cylinder length="0.461" radius="0.05"/>
            </geometry>
            <material name="lightgreen">
                <color rgba="0.5647058823529412 0.9333333333333333 0.5647058823529412 1.0"/>
            </material>
        </visual>
        <collision>
            <origin xyz="0 0 0.2305" rpy="0 0 0"/>
            <geometry>
                <cylinder length="0.461" radius="0.05"/>
            </geometry>
        </collision>
    </link>
    <joint name="sph_joint_x_3" type="revolute">
        <parent link="link3"/>
        <child link="sph_link_x_3"/>
        <origin xyz="0 0 0.461" rpy="0 0 0"/>
        <axis xyz="1 0 0"/>
        <limit lower="-3.14" upper="3.14" effort="10" velocity="1"/>
    </joint>
    <link name="sph_link_x_3">
        <inertial>
            <mass value="0.001"/>
            <inertia ixx="4.000000000000001e-06" iyy="4.000000000000001e-06" izz="4.000000000000001e-06" ixy="0.0" ixz="0.0" iyz="0.0"/>
            <origin xyz="0 0 0" rpy="0 0 0"/>
        </inertial>
        <visual>
            <origin xyz="0 0 0" rpy="0 0 0"/>
            <geometry>
                <sphere radius="0.1"/>
            </geometry>
            <material name="pink">
                <color rgba="1.0 0.7529411764705882 0.796078431372549 1.0"/>
            </material>
        </visual>
    </link>
    <joint name="sph_joint_y_3" type="revolute">
        <parent link="sph_link_x_3"/>
        <child link="sph_link_y_3"/>
        <origin xyz="0 0 0" rpy="0 0 0"/>
        <axis xyz="0 1 0"/>
        <limit lower="-3.14" upper="3.14" effort="10" velocity="1"/>
    </joint>
    <link name="sph_link_y_3">
        <inertial>
            <mass value="0.001"/>
            <inertia ixx="4.000000000000001e-06" iyy="4.000000000000001e-06" izz="4.000000000000001e-06" ixy="0.0" ixz="0.0" iyz="0.0"/>
            <origin xyz="0 0 0" rpy="0 0 0"/>
        </inertial>
        <visual>
            <origin xyz="0 0 0" rpy="0 0 0"/>
            <geometry>
                <sphere radius="0.1"/>
            </geometry>
            <material name="pink">
                <color rgba="1.0 0.7529411764705882 0.796078431372549 1.0"/>
            </material>
        </visual>
    </link>
    <joint name="sph_joint_z_3" type="revolute">
        <parent link="sph_link_y_3"/>
        <child link="sph_link_z_3"/>
        <origin xyz="0 0 0" rpy="0 0 0"/>
        <axis xyz="0 0 1"/>
        <limit lower="-3.14" upper="3.14" effort="10" velocity="1"/>
    </joint>
    <link name="sph_link_z_3">
        <inertial>
            <mass value="0.001"/>
            <inertia ixx="4.000000000000001e-06" iyy="4.000000000000001e-06" izz="4.000000000000001e-06" ixy="0.0" ixz="0.0" iyz="0.0"/>
            <origin xyz="0 0 0" rpy="0 0 0"/>
        </inertial>
        <visual>
            <origin xyz="0 0 0" rpy="0 0 0"/>
            <geometry>
                <sphere radius="0.1"/>
            </geometry>
            <material name="pink">
                <color rgba="1.0 0.7529411764705882 0.796078431372549 1.0"/>
            </material>
        </visual>
    </link>
    <joint name="joint4" type="fixed">
        <parent link="sph_link_z_3"/>
        <child link="link4"/>
        <origin xyz="0 0 0" rpy="0 0 0"/>
    </joint>
    <link name="link4">
        <inertial>
            <mass value="1.0"/>
            <inertia ixx="0.013958333333333336" iyy="0.013958333333333336" izz="0.0012500000000000002" ixy="0.0" ixz="0.0" iyz="0.0"/>
            <origin xyz="0 0 0.2" rpy="0 0 0"/>
        </inertial>
        <visual>
            <origin xyz="0 0 0.2" rpy="0 0 0"/>
            <geometry>
                <cylinder length="0.4" radius="0.05"/>
            </geometry>
            <material name="pink">
                <color rgba="1.0 0.7529411764705882 0.796078431372549 1.0"/>
            </material>
        </visual>
        <collision>
            <origin xyz="0 0 0.2" rpy="0 0 0"/>
            <geometry>
                <cylinder length="0.4" radius="0.05"/>
            </geometry>
        </collision>
    </link>
    <joint name="probe_joint" type="fixed">
        <parent link="link4"/>
        <child link="probe_link"/>
        <origin xyz="0 0 0.4" rpy="0 0 0"/>
    </joint>
    <link name="probe_link">
        <inertial>
            <mass value="0.0"/>
            <inertia ixx="0.0" iyy="0.0" izz="0.0" ixy="0.0" ixz="0.0" iyz="0.0"/>
            <origin xyz="0 0 0" rpy="0 0 0"/>
        </inertial>
        <visual>
            <origin xyz="0 0 0" rpy="0 0 0"/>
            <geometry>
                <cylinder length="0.1" radius="0.01"/>
            </geometry>
            <material name="gray">
                <color rgba="0.5 0.5 0.5 1"/>
            </material>
        </visual>
    </link>
    <joint name="end_effector_joint" type="fixed">
        <parent link="probe_link"/>
        <child link="end_effector"/>
        <origin xyz="0 0 0.1" rpy="0 0 0"/>
    </joint>
    <link name="end_effector">
        <inertial>
            <mass value="0.0"/>
            <inertia ixx="0.0" iyy="0.0" izz="0.0" ixy="0.0" ixz="0.0" iyz="0.0"/>
            <origin xyz="0 0 0" rpy="0 0 0"/>
        </inertial>
        <visual>
            <origin xyz="0 0 0" rpy="0 0 0"/>
            <geometry>
                <cylinder length="0" radius="0"/>
            </geometry>
            <material name="gray">
                <color rgba="0.5 0.5 0.5 1"/>
            </material>
        </visual>
    </link>
</robot>
