<?xml version="1.0" ?>
<robot name="test_robot">
    <link name="base_link">
        <inertial>
            <mass value="1.0"/>
            <inertia ixx="0.010416666666666666" iyy="0.010416666666666666" izz="0.010416666666666666" ixy="0.0" ixz="0.0" iyz="0.0"/>
            <origin xyz="0 0 0" rpy="0 0 0"/>
        </inertial>
        <visual>
            <origin xyz="0 0 0" rpy="0 0 0"/>
            <geometry>
                <box size="0.25 0.25 0.25"/>
            </geometry>
            <material name="gray">
                <color rgba="0.5 0.5 0.5 1"/>
            </material>
        </visual>
    </link>
    <joint name="joint0_fixed" type="fixed">
        <parent link="base_link"/>
        <child link="link0_fixed"/>
        <origin xyz="0 0 0.125" rpy="0 0 0"/>
    </joint>
    <link name="link0_fixed">
        <inertial>
            <mass value="1.0"/>
            <inertia ixx="0.10166666666666668" iyy="0.10166666666666668" izz="0.10166666666666668" ixy="0.0" ixz="0.0" iyz="0.0"/>
            <origin xyz="0 0 -0.025" rpy="0 0 0"/>
        </inertial>
        <visual>
            <origin xyz="0 0 -0.025" rpy="0 0 0"/>
            <geometry>
                <box size="1.1 0.1 0.05"/>
            </geometry>
            <material name="lightgreen">
                <color rgba="0.5647058823529412 0.9333333333333333 0.5647058823529412 1.0"/>
            </material>
        </visual>
        <collision>
            <origin xyz="0 0 -0.025" rpy="0 0 0"/>
            <geometry>
                <box size="1.1 0.1 0.05"/>
            </geometry>
        </collision>
    </link>
    <joint name="joint0" type="prismatic">
        <parent link="link0_fixed"/>
        <child link="link0"/>
        <origin xyz="0 0 0" rpy="0 0 0"/>
        <axis xyz="1 0 0"/>
        <limit lower="-0.5" upper="0.5" effort="10" velocity="1"/>
    </joint>
    <link name="link0">
        <inertial>
            <mass value="1.0"/>
            <inertia ixx="0.0008333333333333335" iyy="0.0008333333333333335" izz="0.0012500000000000002" ixy="0.0" ixz="0.0" iyz="0.0"/>
            <origin xyz="0 0 0.025" rpy="0 0 0"/>
        </inertial>
        <visual>
            <origin xyz="0 0 0.025" rpy="0 0 0"/>
            <geometry>
                <cylinder length="0.05" radius="0.05"/>
            </geometry>
            <material name="lightgreen">
                <color rgba="0.5647058823529412 0.9333333333333333 0.5647058823529412 1.0"/>
            </material>
        </visual>
        <collision>
            <origin xyz="0 0 0.025" rpy="0 0 0"/>
            <geometry>
                <cylinder length="0.05" radius="0.05"/>
            </geometry>
        </collision>
    </link>
    <joint name="joint1_fixed" type="fixed">
        <parent link="link0"/>
        <child link="link1_fixed"/>
        <origin xyz="0 0 0.05" rpy="0 0 0"/>
    </joint>
    <link name="link1_fixed">
        <inertial>
            <mass value="1.0"/>
            <inertia ixx="0.10166666666666668" iyy="0.10166666666666668" izz="0.10166666666666668" ixy="0.0" ixz="0.0" iyz="0.0"/>
            <origin xyz="0 0 -0.025" rpy="0 0 0"/>
        </inertial>
        <visual>
            <origin xyz="0 0 -0.025" rpy="0 0 0"/>
            <geometry>
                <box size="0.1 1.1 0.05"/>
            </geometry>
            <material name="lightpink">
                <color rgba="1.0 0.7137254901960784 0.7568627450980392 1.0"/>
            </material>
        </visual>
        <collision>
            <origin xyz="0 0 -0.025" rpy="0 0 0"/>
            <geometry>
                <box size="0.1 1.1 0.05"/>
            </geometry>
        </collision>
    </link>
    <joint name="joint1" type="prismatic">
        <parent link="link1_fixed"/>
        <child link="link1"/>
        <origin xyz="0 0 0" rpy="0 0 0"/>
        <axis xyz="0 1 0"/>
        <limit lower="-0.5" upper="0.5" effort="10" velocity="1"/>
    </joint>
    <link name="link1">
        <inertial>
            <mass value="1.0"/>
            <inertia ixx="0.0008333333333333335" iyy="0.0008333333333333335" izz="0.0012500000000000002" ixy="0.0" ixz="0.0" iyz="0.0"/>
            <origin xyz="0 0 0.025" rpy="0 0 0"/>
        </inertial>
        <visual>
            <origin xyz="0 0 0.025" rpy="0 0 0"/>
            <geometry>
                <cylinder length="0.05" radius="0.05"/>
            </geometry>
            <material name="lightpink">
                <color rgba="1.0 0.7137254901960784 0.7568627450980392 1.0"/>
            </material>
        </visual>
        <collision>
            <origin xyz="0 0 0.025" rpy="0 0 0"/>
            <geometry>
                <cylinder length="0.05" radius="0.05"/>
            </geometry>
        </collision>
    </link>
    <joint name="joint_viz2" type="fixed">
        <parent link="link1"/>
        <child link="joint_viz_link2"/>
        <origin xyz="0 0 0.05" rpy="0 0 0"/>
    </joint>
    <link name="joint_viz_link2">
        <inertial>
            <mass value="0.0"/>
            <inertia ixx="0.0" iyy="0.0" izz="0.0" ixy="0.0" ixz="0.0" iyz="0.0"/>
            <origin xyz="0 0 0" rpy="0 1.57 0"/>
        </inertial>
        <visual>
            <origin xyz="0 0 0" rpy="0 1.57 0"/>
            <geometry>
                <cylinder length="0.125" radius="0.06"/>
            </geometry>
            <material name="cornsilk">
                <color rgba="1.0 0.9725490196078431 0.8627450980392157 1.0"/>
            </material>
        </visual>
    </link>
    <joint name="joint2" type="revolute">
        <parent link="link1"/>
        <child link="link2"/>
        <origin xyz="0 0 0.05" rpy="0 0 0"/>
        <axis xyz="1 0 0"/>
        <limit lower="-3.14" upper="3.14" effort="10" velocity="1"/>
    </joint>
    <link name="link2">
        <inertial>
            <mass value="1.0"/>
            <inertia ixx="0.047499999999999994" iyy="0.047499999999999994" izz="0.0012500000000000002" ixy="0.0" ixz="0.0" iyz="0.0"/>
            <origin xyz="0 0 0.375" rpy="0 0 0"/>
        </inertial>
        <visual>
            <origin xyz="0 0 0.375" rpy="0 0 0"/>
            <geometry>
                <cylinder length="0.75" radius="0.05"/>
            </geometry>
            <material name="cornsilk">
                <color rgba="1.0 0.9725490196078431 0.8627450980392157 1.0"/>
            </material>
        </visual>
        <collision>
            <origin xyz="0 0 0.375" rpy="0 0 0"/>
            <geometry>
                <cylinder length="0.75" radius="0.05"/>
            </geometry>
        </collision>
    </link>
    <joint name="joint3" type="prismatic">
        <parent link="link2"/>
        <child link="link3"/>
        <origin xyz="0 0 0.061" rpy="0 0 0"/>
        <axis xyz="0 0 1"/>
        <limit lower="0" upper="0.7" effort="10" velocity="1"/>
    </joint>
    <link name="link3">
        <inertial>
            <mass value="1.0"/>
            <inertia ixx="0.04275174999999999" iyy="0.04275174999999999" izz="0.0012500000000000002" ixy="0.0" ixz="0.0" iyz="0.0"/>
            <origin xyz="0 0 0.3555" rpy="0 0 0"/>
        </inertial>
        <visual>
            <origin xyz="0 0 0.3555" rpy="0 0 0"/>
            <geometry>
                <cylinder length="0.711" radius="0.05"/>
            </geometry>
            <material name="mistyrose">
                <color rgba="1.0 0.8941176470588236 0.8823529411764706 1.0"/>
            </material>
        </visual>
        <collision>
            <origin xyz="0 0 0.3555" rpy="0 0 0"/>
            <geometry>
                <cylinder length="0.711" radius="0.05"/>
            </geometry>
        </collision>
    </link>
    <joint name="sph_joint_x_1" type="revolute">
        <parent link="link3"/>
        <child link="sph_link_x_1"/>
        <origin xyz="0 0 0.711" rpy="0 0 0"/>
        <axis xyz="1 0 0"/>
        <limit lower="-3.14" upper="3.14" effort="10" velocity="1"/>
    </joint>
    <link name="sph_link_x_1">
        <inertial>
            <mass value="0.001"/>
            <inertia ixx="4.000000000000001e-06" iyy="4.000000000000001e-06" izz="4.000000000000001e-06" ixy="0.0" ixz="0.0" iyz="0.0"/>
            <origin xyz="0 0 0" rpy="0 0 0"/>
        </inertial>
        <visual>
            <origin xyz="0 0 0" rpy="0 0 0"/>
            <geometry>
                <sphere radius="0.1"/>
            </geometry>
            <material name="coral">
                <color rgba="1.0 0.4980392156862745 0.3137254901960784 1.0"/>
            </material>
        </visual>
    </link>
    <joint name="sph_joint_y_1" type="revolute">
        <parent link="sph_link_x_1"/>
        <child link="sph_link_y_1"/>
        <origin xyz="0 0 0" rpy="0 0 0"/>
        <axis xyz="0 1 0"/>
        <limit lower="-3.14" upper="3.14" effort="10" velocity="1"/>
    </joint>
    <link name="sph_link_y_1">
        <inertial>
            <mass value="0.001"/>
            <inertia ixx="4.000000000000001e-06" iyy="4.000000000000001e-06" izz="4.000000000000001e-06" ixy="0.0" ixz="0.0" iyz="0.0"/>
            <origin xyz="0 0 0" rpy="0 0 0"/>
        </inertial>
        <visual>
            <origin xyz="0 0 0" rpy="0 0 0"/>
            <geometry>
                <sphere radius="0.1"/>
            </geometry>
            <material name="coral">
                <color rgba="1.0 0.4980392156862745 0.3137254901960784 1.0"/>
            </material>
        </visual>
    </link>
    <joint name="sph_joint_z_1" type="revolute">
        <parent link="sph_link_y_1"/>
        <child link="sph_link_z_1"/>
        <origin xyz="0 0 0" rpy="0 0 0"/>
        <axis xyz="0 0 1"/>
        <limit lower="-3.14" upper="3.14" effort="10" velocity="1"/>
    </joint>
    <link name="sph_link_z_1">
        <inertial>
            <mass value="0.001"/>
            <inertia ixx="4.000000000000001e-06" iyy="4.000000000000001e-06" izz="4.000000000000001e-06" ixy="0.0" ixz="0.0" iyz="0.0"/>
            <origin xyz="0 0 0" rpy="0 0 0"/>
        </inertial>
        <visual>
            <origin xyz="0 0 0" rpy="0 0 0"/>
            <geometry>
                <sphere radius="0.1"/>
            </geometry>
            <material name="coral">
                <color rgba="1.0 0.4980392156862745 0.3137254901960784 1.0"/>
            </material>
        </visual>
    </link>
    <joint name="joint4" type="fixed">
        <parent link="sph_link_z_1"/>
        <child link="link4"/>
        <origin xyz="0 0 0" rpy="0 0 0"/>
    </joint>
    <link name="link4">
        <inertial>
            <mass value="1.0"/>
            <inertia ixx="0.030625" iyy="0.030625" izz="0.0012500000000000002" ixy="0.0" ixz="0.0" iyz="0.0"/>
            <origin xyz="0 0 0.3" rpy="0 0 0"/>
        </inertial>
        <visual>
            <origin xyz="0 0 0.3" rpy="0 0 0"/>
            <geometry>
                <cylinder length="0.6" radius="0.05"/>
            </geometry>
            <material name="coral">
                <color rgba="1.0 0.4980392156862745 0.3137254901960784 1.0"/>
            </material>
        </visual>
        <collision>
            <origin xyz="0 0 0.3" rpy="0 0 0"/>
            <geometry>
                <cylinder length="0.6" radius="0.05"/>
            </geometry>
        </collision>
    </link>
    <joint name="joint5" type="prismatic">
        <parent link="link4"/>
        <child link="link5"/>
        <origin xyz="0 0 0.061" rpy="0 0 0"/>
        <axis xyz="0 0 1"/>
        <limit lower="0" upper="0.5499999999999999" effort="10" velocity="1"/>
    </joint>
    <link name="link5">
        <inertial>
            <mass value="1.0"/>
            <inertia ixx="0.026851749999999994" iyy="0.026851749999999994" izz="0.0012500000000000002" ixy="0.0" ixz="0.0" iyz="0.0"/>
            <origin xyz="0 0 0.28049999999999997" rpy="0 0 0"/>
        </inertial>
        <visual>
            <origin xyz="0 0 0.28049999999999997" rpy="0 0 0"/>
            <geometry>
                <cylinder length="0.5609999999999999" radius="0.05"/>
            </geometry>
            <material name="blue">
                <color rgba="0.0 0.0 1.0 1.0"/>
            </material>
        </visual>
        <collision>
            <origin xyz="0 0 0.28049999999999997" rpy="0 0 0"/>
            <geometry>
                <cylinder length="0.5609999999999999" radius="0.05"/>
            </geometry>
        </collision>
    </link>
    <joint name="probe_joint" type="fixed">
        <parent link="link5"/>
        <child link="probe_link"/>
        <origin xyz="0 0 0.5609999999999999" rpy="0 0 0"/>
    </joint>
    <link name="probe_link">
        <inertial>
            <mass value="0.0"/>
            <inertia ixx="0.0" iyy="0.0" izz="0.0" ixy="0.0" ixz="0.0" iyz="0.0"/>
            <origin xyz="0 0 0" rpy="0 0 0"/>
        </inertial>
        <visual>
            <origin xyz="0 0 0" rpy="0 0 0"/>
            <geometry>
                <cylinder length="0.1" radius="0.01"/>
            </geometry>
            <material name="gray">
                <color rgba="0.5 0.5 0.5 1"/>
            </material>
        </visual>
    </link>
    <joint name="end_effector_joint" type="fixed">
        <parent link="probe_link"/>
        <child link="end_effector"/>
        <origin xyz="0 0 0.1" rpy="0 0 0"/>
    </joint>
    <link name="end_effector">
        <inertial>
            <mass value="0.0"/>
            <inertia ixx="0.0" iyy="0.0" izz="0.0" ixy="0.0" ixz="0.0" iyz="0.0"/>
            <origin xyz="0 0 0" rpy="0 0 0"/>
        </inertial>
        <visual>
            <origin xyz="0 0 0" rpy="0 0 0"/>
            <geometry>
                <cylinder length="0" radius="0"/>
            </geometry>
            <material name="gray">
                <color rgba="0.5 0.5 0.5 1"/>
            </material>
        </visual>
    </link>
</robot>
