<?xml version="1.0" ?>
<robot name="test_robot">
    <link name="base_link">
        <inertial>
            <mass value="1.0"/>
            <inertia ixx="0.010416666666666666" iyy="0.010416666666666666" izz="0.010416666666666666" ixy="0.0" ixz="0.0" iyz="0.0"/>
            <origin xyz="0 0 0" rpy="0 0 0"/>
        </inertial>
        <visual>
            <origin xyz="0 0 0" rpy="0 0 0"/>
            <geometry>
                <box size="0.25 0.25 0.25"/>
            </geometry>
            <material name="gray">
                <color rgba="0.5 0.5 0.5 1"/>
            </material>
        </visual>
    </link>
    <joint name="sph_joint_x_1" type="revolute">
        <parent link="base_link"/>
        <child link="sph_link_x_1"/>
        <origin xyz="0 0 0.125" rpy="0 0 0"/>
        <axis xyz="1 0 0"/>
        <limit lower="-3.14" upper="3.14" effort="10" velocity="1"/>
    </joint>
    <link name="sph_link_x_1">
        <inertial>
            <mass value="0.001"/>
            <inertia ixx="4.000000000000001e-06" iyy="4.000000000000001e-06" izz="4.000000000000001e-06" ixy="0.0" ixz="0.0" iyz="0.0"/>
            <origin xyz="0 0 0" rpy="0 0 0"/>
        </inertial>
        <visual>
            <origin xyz="0 0 0" rpy="0 0 0"/>
            <geometry>
                <sphere radius="0.1"/>
            </geometry>
            <material name="antiquewhite">
                <color rgba="0.9803921568627451 0.9215686274509803 0.8431372549019608 1.0"/>
            </material>
        </visual>
    </link>
    <joint name="sph_joint_y_1" type="revolute">
        <parent link="sph_link_x_1"/>
        <child link="sph_link_y_1"/>
        <origin xyz="0 0 0" rpy="0 0 0"/>
        <axis xyz="0 1 0"/>
        <limit lower="-3.14" upper="3.14" effort="10" velocity="1"/>
    </joint>
    <link name="sph_link_y_1">
        <inertial>
            <mass value="0.001"/>
            <inertia ixx="4.000000000000001e-06" iyy="4.000000000000001e-06" izz="4.000000000000001e-06" ixy="0.0" ixz="0.0" iyz="0.0"/>
            <origin xyz="0 0 0" rpy="0 0 0"/>
        </inertial>
        <visual>
            <origin xyz="0 0 0" rpy="0 0 0"/>
            <geometry>
                <sphere radius="0.1"/>
            </geometry>
            <material name="antiquewhite">
                <color rgba="0.9803921568627451 0.9215686274509803 0.8431372549019608 1.0"/>
            </material>
        </visual>
    </link>
    <joint name="sph_joint_z_1" type="revolute">
        <parent link="sph_link_y_1"/>
        <child link="sph_link_z_1"/>
        <origin xyz="0 0 0" rpy="0 0 0"/>
        <axis xyz="0 0 1"/>
        <limit lower="-3.14" upper="3.14" effort="10" velocity="1"/>
    </joint>
    <link name="sph_link_z_1">
        <inertial>
            <mass value="0.001"/>
            <inertia ixx="4.000000000000001e-06" iyy="4.000000000000001e-06" izz="4.000000000000001e-06" ixy="0.0" ixz="0.0" iyz="0.0"/>
            <origin xyz="0 0 0" rpy="0 0 0"/>
        </inertial>
        <visual>
            <origin xyz="0 0 0" rpy="0 0 0"/>
            <geometry>
                <sphere radius="0.1"/>
            </geometry>
            <material name="antiquewhite">
                <color rgba="0.9803921568627451 0.9215686274509803 0.8431372549019608 1.0"/>
            </material>
        </visual>
    </link>
    <joint name="joint0" type="fixed">
        <parent link="sph_link_z_1"/>
        <child link="link0"/>
        <origin xyz="0 0 0" rpy="0 0 0"/>
    </joint>
    <link name="link0">
        <inertial>
            <mass value="1.0"/>
            <inertia ixx="0.021458333333333333" iyy="0.021458333333333333" izz="0.0012500000000000002" ixy="0.0" ixz="0.0" iyz="0.0"/>
            <origin xyz="0 0 0.25" rpy="0 0 0"/>
        </inertial>
        <visual>
            <origin xyz="0 0 0.25" rpy="0 0 0"/>
            <geometry>
                <cylinder length="0.5" radius="0.05"/>
            </geometry>
            <material name="antiquewhite">
                <color rgba="0.9803921568627451 0.9215686274509803 0.8431372549019608 1.0"/>
            </material>
        </visual>
        <collision>
            <origin xyz="0 0 0.25" rpy="0 0 0"/>
            <geometry>
                <cylinder length="0.5" radius="0.05"/>
            </geometry>
        </collision>
    </link>
    <joint name="joint_viz1" type="fixed">
        <parent link="link0"/>
        <child link="joint_viz_link1"/>
        <origin xyz="0 0 0.5" rpy="0 0 0"/>
    </joint>
    <link name="joint_viz_link1">
        <inertial>
            <mass value="0.0"/>
            <inertia ixx="0.0" iyy="0.0" izz="0.0" ixy="0.0" ixz="0.0" iyz="0.0"/>
            <origin xyz="0 0 0" rpy="0 1.57 0"/>
        </inertial>
        <visual>
            <origin xyz="0 0 0" rpy="0 1.57 0"/>
            <geometry>
                <cylinder length="0.125" radius="0.06"/>
            </geometry>
            <material name="lightslategray">
                <color rgba="0.4666666666666667 0.5333333333333333 0.6 1.0"/>
            </material>
        </visual>
    </link>
    <joint name="joint1" type="revolute">
        <parent link="link0"/>
        <child link="link1"/>
        <origin xyz="0 0 0.5" rpy="0 0 0"/>
        <axis xyz="1 0 0"/>
        <limit lower="-3.14" upper="3.14" effort="10" velocity="1"/>
    </joint>
    <link name="link1">
        <inertial>
            <mass value="1.0"/>
            <inertia ixx="0.021458333333333333" iyy="0.021458333333333333" izz="0.0012500000000000002" ixy="0.0" ixz="0.0" iyz="0.0"/>
            <origin xyz="0 0 0.25" rpy="0 0 0"/>
        </inertial>
        <visual>
            <origin xyz="0 0 0.25" rpy="0 0 0"/>
            <geometry>
                <cylinder length="0.5" radius="0.05"/>
            </geometry>
            <material name="lightslategray">
                <color rgba="0.4666666666666667 0.5333333333333333 0.6 1.0"/>
            </material>
        </visual>
        <collision>
            <origin xyz="0 0 0.25" rpy="0 0 0"/>
            <geometry>
                <cylinder length="0.5" radius="0.05"/>
            </geometry>
        </collision>
    </link>
    <joint name="joint2" type="prismatic">
        <parent link="link1"/>
        <child link="link2"/>
        <origin xyz="0 0 0.5" rpy="0 0 0"/>
        <axis xyz="0 0 1"/>
        <limit lower="-0.5" upper="0.5" effort="10" velocity="1"/>
    </joint>
    <link name="link2">
        <inertial>
            <mass value="1.0"/>
            <inertia ixx="0.008125" iyy="0.008125" izz="0.0012500000000000002" ixy="0.0" ixz="0.0" iyz="0.0"/>
            <origin xyz="0 0 0.15" rpy="0 0 0"/>
        </inertial>
        <visual>
            <origin xyz="0 0 0.15" rpy="0 0 0"/>
            <geometry>
                <cylinder length="0.3" radius="0.05"/>
            </geometry>
            <material name="saddlebrown">
                <color rgba="0.5450980392156862 0.27058823529411763 0.07450980392156863 1.0"/>
            </material>
        </visual>
        <collision>
            <origin xyz="0 0 0.15" rpy="0 0 0"/>
            <geometry>
                <cylinder length="0.3" radius="0.05"/>
            </geometry>
        </collision>
    </link>
    <joint name="joint_viz3" type="fixed">
        <parent link="link2"/>
        <child link="joint_viz_link3"/>
        <origin xyz="0 0 0.3" rpy="0 0 0"/>
    </joint>
    <link name="joint_viz_link3">
        <inertial>
            <mass value="0.0"/>
            <inertia ixx="0.0" iyy="0.0" izz="0.0" ixy="0.0" ixz="0.0" iyz="0.0"/>
            <origin xyz="0 0 0" rpy="0 1.57 0"/>
        </inertial>
        <visual>
            <origin xyz="0 0 0" rpy="0 1.57 0"/>
            <geometry>
                <cylinder length="0.125" radius="0.06"/>
            </geometry>
            <material name="white">
                <color rgba="1.0 1.0 1.0 1.0"/>
            </material>
        </visual>
    </link>
    <joint name="joint3" type="revolute">
        <parent link="link2"/>
        <child link="link3"/>
        <origin xyz="0 0 0.3" rpy="0 0 0"/>
        <axis xyz="1 0 0"/>
        <limit lower="-3.14" upper="3.14" effort="10" velocity="1"/>
    </joint>
    <link name="link3">
        <inertial>
            <mass value="1.0"/>
            <inertia ixx="0.021458333333333333" iyy="0.021458333333333333" izz="0.0012500000000000002" ixy="0.0" ixz="0.0" iyz="0.0"/>
            <origin xyz="0 0 0.25" rpy="0 0 0"/>
        </inertial>
        <visual>
            <origin xyz="0 0 0.25" rpy="0 0 0"/>
            <geometry>
                <cylinder length="0.5" radius="0.05"/>
            </geometry>
            <material name="white">
                <color rgba="1.0 1.0 1.0 1.0"/>
            </material>
        </visual>
        <collision>
            <origin xyz="0 0 0.25" rpy="0 0 0"/>
            <geometry>
                <cylinder length="0.5" radius="0.05"/>
            </geometry>
        </collision>
    </link>
    <joint name="joint_viz4" type="fixed">
        <parent link="link3"/>
        <child link="joint_viz_link4"/>
        <origin xyz="0 0 0.5" rpy="0 0 0"/>
    </joint>
    <link name="joint_viz_link4">
        <inertial>
            <mass value="0.0"/>
            <inertia ixx="0.0" iyy="0.0" izz="0.0" ixy="0.0" ixz="0.0" iyz="0.0"/>
            <origin xyz="0 0 0" rpy="0 1.57 0"/>
        </inertial>
        <visual>
            <origin xyz="0 0 0" rpy="0 1.57 0"/>
            <geometry>
                <cylinder length="0.125" radius="0.06"/>
            </geometry>
            <material name="gray">
                <color rgba="0.5019607843137255 0.5019607843137255 0.5019607843137255 1.0"/>
            </material>
        </visual>
    </link>
    <joint name="joint4" type="revolute">
        <parent link="link3"/>
        <child link="link4"/>
        <origin xyz="0 0 0.5" rpy="0 0 0"/>
        <axis xyz="1 0 0"/>
        <limit lower="-3.14" upper="3.14" effort="10" velocity="1"/>
    </joint>
    <link name="link4">
        <inertial>
            <mass value="1.0"/>
            <inertia ixx="0.01083333333333333" iyy="0.01083333333333333" izz="0.0012500000000000002" ixy="0.0" ixz="0.0" iyz="0.0"/>
            <origin xyz="0 0 0.175" rpy="0 0 0"/>
        </inertial>
        <visual>
            <origin xyz="0 0 0.175" rpy="0 0 0"/>
            <geometry>
                <cylinder length="0.35" radius="0.05"/>
            </geometry>
            <material name="gray">
                <color rgba="0.5019607843137255 0.5019607843137255 0.5019607843137255 1.0"/>
            </material>
        </visual>
        <collision>
            <origin xyz="0 0 0.175" rpy="0 0 0"/>
            <geometry>
                <cylinder length="0.35" radius="0.05"/>
            </geometry>
        </collision>
    </link>
    <joint name="joint_viz5" type="fixed">
        <parent link="link4"/>
        <child link="joint_viz_link5"/>
        <origin xyz="0 0 0.35" rpy="0 0 0"/>
    </joint>
    <link name="joint_viz_link5">
        <inertial>
            <mass value="0.0"/>
            <inertia ixx="0.0" iyy="0.0" izz="0.0" ixy="0.0" ixz="0.0" iyz="0.0"/>
            <origin xyz="0 0 0" rpy="1.57 0 0"/>
        </inertial>
        <visual>
            <origin xyz="0 0 0" rpy="1.57 0 0"/>
            <geometry>
                <cylinder length="0.125" radius="0.06"/>
            </geometry>
            <material name="salmon">
                <color rgba="0.9803921568627451 0.5019607843137255 0.4470588235294118 1.0"/>
            </material>
        </visual>
    </link>
    <joint name="joint5" type="revolute">
        <parent link="link4"/>
        <child link="link5"/>
        <origin xyz="0 0 0.35" rpy="0 0 0"/>
        <axis xyz="0 1 0"/>
        <limit lower="-3.14" upper="3.14" effort="10" velocity="1"/>
    </joint>
    <link name="link5">
        <inertial>
            <mass value="1.0"/>
            <inertia ixx="0.0014583333333333334" iyy="0.0014583333333333334" izz="0.0012500000000000002" ixy="0.0" ixz="0.0" iyz="0.0"/>
            <origin xyz="0 0 0.05" rpy="0 0 0"/>
        </inertial>
        <visual>
            <origin xyz="0 0 0.05" rpy="0 0 0"/>
            <geometry>
                <cylinder length="0.1" radius="0.05"/>
            </geometry>
            <material name="salmon">
                <color rgba="0.9803921568627451 0.5019607843137255 0.4470588235294118 1.0"/>
            </material>
        </visual>
        <collision>
            <origin xyz="0 0 0.05" rpy="0 0 0"/>
            <geometry>
                <cylinder length="0.1" radius="0.05"/>
            </geometry>
        </collision>
    </link>
    <joint name="probe_joint" type="fixed">
        <parent link="link5"/>
        <child link="probe_link"/>
        <origin xyz="0 0 0.1" rpy="0 0 0"/>
    </joint>
    <link name="probe_link">
        <inertial>
            <mass value="0.0"/>
            <inertia ixx="0.0" iyy="0.0" izz="0.0" ixy="0.0" ixz="0.0" iyz="0.0"/>
            <origin xyz="0 0 0" rpy="0 0 0"/>
        </inertial>
        <visual>
            <origin xyz="0 0 0" rpy="0 0 0"/>
            <geometry>
                <cylinder length="0.1" radius="0.01"/>
            </geometry>
            <material name="gray">
                <color rgba="0.5 0.5 0.5 1"/>
            </material>
        </visual>
    </link>
    <joint name="end_effector_joint" type="fixed">
        <parent link="probe_link"/>
        <child link="end_effector"/>
        <origin xyz="0 0 0.1" rpy="0 0 0"/>
    </joint>
    <link name="end_effector">
        <inertial>
            <mass value="0.0"/>
            <inertia ixx="0.0" iyy="0.0" izz="0.0" ixy="0.0" ixz="0.0" iyz="0.0"/>
            <origin xyz="0 0 0" rpy="0 0 0"/>
        </inertial>
        <visual>
            <origin xyz="0 0 0" rpy="0 0 0"/>
            <geometry>
                <cylinder length="0" radius="0"/>
            </geometry>
            <material name="gray">
                <color rgba="0.5 0.5 0.5 1"/>
            </material>
        </visual>
    </link>
</robot>
