<?xml version="1.0" ?>
<robot name="test_robot">
    <link name="base_link">
        <inertial>
            <mass value="1.0"/>
            <inertia ixx="0.010416666666666666" iyy="0.010416666666666666" izz="0.010416666666666666" ixy="0.0" ixz="0.0" iyz="0.0"/>
            <origin xyz="0 0 0" rpy="0 0 0"/>
        </inertial>
        <visual>
            <origin xyz="0 0 0" rpy="0 0 0"/>
            <geometry>
                <box size="0.25 0.25 0.25"/>
            </geometry>
            <material name="gray">
                <color rgba="0.5 0.5 0.5 1"/>
            </material>
        </visual>
    </link>
    <joint name="sph_joint_x_1" type="revolute">
        <parent link="base_link"/>
        <child link="sph_link_x_1"/>
        <origin xyz="0 0 0.125" rpy="0 0 0"/>
        <axis xyz="1 0 0"/>
        <limit lower="-3.14" upper="3.14" effort="10" velocity="1"/>
    </joint>
    <link name="sph_link_x_1">
        <inertial>
            <mass value="0.001"/>
            <inertia ixx="4.000000000000001e-06" iyy="4.000000000000001e-06" izz="4.000000000000001e-06" ixy="0.0" ixz="0.0" iyz="0.0"/>
            <origin xyz="0 0 0" rpy="0 0 0"/>
        </inertial>
        <visual>
            <origin xyz="0 0 0" rpy="0 0 0"/>
            <geometry>
                <sphere radius="0.1"/>
            </geometry>
            <material name="greenyellow">
                <color rgba="0.6784313725490196 1.0 0.1843137254901961 1.0"/>
            </material>
        </visual>
    </link>
    <joint name="sph_joint_y_1" type="revolute">
        <parent link="sph_link_x_1"/>
        <child link="sph_link_y_1"/>
        <origin xyz="0 0 0" rpy="0 0 0"/>
        <axis xyz="0 1 0"/>
        <limit lower="-3.14" upper="3.14" effort="10" velocity="1"/>
    </joint>
    <link name="sph_link_y_1">
        <inertial>
            <mass value="0.001"/>
            <inertia ixx="4.000000000000001e-06" iyy="4.000000000000001e-06" izz="4.000000000000001e-06" ixy="0.0" ixz="0.0" iyz="0.0"/>
            <origin xyz="0 0 0" rpy="0 0 0"/>
        </inertial>
        <visual>
            <origin xyz="0 0 0" rpy="0 0 0"/>
            <geometry>
                <sphere radius="0.1"/>
            </geometry>
            <material name="greenyellow">
                <color rgba="0.6784313725490196 1.0 0.1843137254901961 1.0"/>
            </material>
        </visual>
    </link>
    <joint name="sph_joint_z_1" type="revolute">
        <parent link="sph_link_y_1"/>
        <child link="sph_link_z_1"/>
        <origin xyz="0 0 0" rpy="0 0 0"/>
        <axis xyz="0 0 1"/>
        <limit lower="-3.14" upper="3.14" effort="10" velocity="1"/>
    </joint>
    <link name="sph_link_z_1">
        <inertial>
            <mass value="0.001"/>
            <inertia ixx="4.000000000000001e-06" iyy="4.000000000000001e-06" izz="4.000000000000001e-06" ixy="0.0" ixz="0.0" iyz="0.0"/>
            <origin xyz="0 0 0" rpy="0 0 0"/>
        </inertial>
        <visual>
            <origin xyz="0 0 0" rpy="0 0 0"/>
            <geometry>
                <sphere radius="0.1"/>
            </geometry>
            <material name="greenyellow">
                <color rgba="0.6784313725490196 1.0 0.1843137254901961 1.0"/>
            </material>
        </visual>
    </link>
    <joint name="joint0" type="fixed">
        <parent link="sph_link_z_1"/>
        <child link="link0"/>
        <origin xyz="0 0 0" rpy="0 0 0"/>
    </joint>
    <link name="link0">
        <inertial>
            <mass value="1.0"/>
            <inertia ixx="0.047499999999999994" iyy="0.047499999999999994" izz="0.0012500000000000002" ixy="0.0" ixz="0.0" iyz="0.0"/>
            <origin xyz="0 0 0.375" rpy="0 0 0"/>
        </inertial>
        <visual>
            <origin xyz="0 0 0.375" rpy="0 0 0"/>
            <geometry>
                <cylinder length="0.75" radius="0.05"/>
            </geometry>
            <material name="greenyellow">
                <color rgba="0.6784313725490196 1.0 0.1843137254901961 1.0"/>
            </material>
        </visual>
        <collision>
            <origin xyz="0 0 0.375" rpy="0 0 0"/>
            <geometry>
                <cylinder length="0.75" radius="0.05"/>
            </geometry>
        </collision>
    </link>
    <joint name="joint1" type="prismatic">
        <parent link="link0"/>
        <child link="link1"/>
        <origin xyz="0 0 0.75" rpy="0 0 0"/>
        <axis xyz="0 1 0"/>
        <limit lower="-0.5" upper="0.5" effort="10" velocity="1"/>
    </joint>
    <link name="link1">
        <inertial>
            <mass value="1.0"/>
            <inertia ixx="0.041458333333333326" iyy="0.041458333333333326" izz="0.0012500000000000002" ixy="0.0" ixz="0.0" iyz="0.0"/>
            <origin xyz="0 0 0.35" rpy="0 0 0"/>
        </inertial>
        <visual>
            <origin xyz="0 0 0.35" rpy="0 0 0"/>
            <geometry>
                <cylinder length="0.7" radius="0.05"/>
            </geometry>
            <material name="moccasin">
                <color rgba="1.0 0.8941176470588236 0.7098039215686275 1.0"/>
            </material>
        </visual>
        <collision>
            <origin xyz="0 0 0.35" rpy="0 0 0"/>
            <geometry>
                <cylinder length="0.7" radius="0.05"/>
            </geometry>
        </collision>
    </link>
    <joint name="joint2" type="prismatic">
        <parent link="link1"/>
        <child link="link2"/>
        <origin xyz="0 0 0.7" rpy="0 0 0"/>
        <axis xyz="0 0 1"/>
        <limit lower="-0.5" upper="0.5" effort="10" velocity="1"/>
    </joint>
    <link name="link2">
        <inertial>
            <mass value="1.0"/>
            <inertia ixx="0.041458333333333326" iyy="0.041458333333333326" izz="0.0012500000000000002" ixy="0.0" ixz="0.0" iyz="0.0"/>
            <origin xyz="0 0 0.35" rpy="0 0 0"/>
        </inertial>
        <visual>
            <origin xyz="0 0 0.35" rpy="0 0 0"/>
            <geometry>
                <cylinder length="0.7" radius="0.05"/>
            </geometry>
            <material name="mediumslateblue">
                <color rgba="0.4823529411764706 0.40784313725490196 0.9333333333333333 1.0"/>
            </material>
        </visual>
        <collision>
            <origin xyz="0 0 0.35" rpy="0 0 0"/>
            <geometry>
                <cylinder length="0.7" radius="0.05"/>
            </geometry>
        </collision>
    </link>
    <joint name="sph_joint_x_2" type="revolute">
        <parent link="link2"/>
        <child link="sph_link_x_2"/>
        <origin xyz="0 0 0.7" rpy="0 0 0"/>
        <axis xyz="1 0 0"/>
        <limit lower="-3.14" upper="3.14" effort="10" velocity="1"/>
    </joint>
    <link name="sph_link_x_2">
        <inertial>
            <mass value="0.001"/>
            <inertia ixx="4.000000000000001e-06" iyy="4.000000000000001e-06" izz="4.000000000000001e-06" ixy="0.0" ixz="0.0" iyz="0.0"/>
            <origin xyz="0 0 0" rpy="0 0 0"/>
        </inertial>
        <visual>
            <origin xyz="0 0 0" rpy="0 0 0"/>
            <geometry>
                <sphere radius="0.1"/>
            </geometry>
            <material name="cyan">
                <color rgba="0.0 1.0 1.0 1.0"/>
            </material>
        </visual>
    </link>
    <joint name="sph_joint_y_2" type="revolute">
        <parent link="sph_link_x_2"/>
        <child link="sph_link_y_2"/>
        <origin xyz="0 0 0" rpy="0 0 0"/>
        <axis xyz="0 1 0"/>
        <limit lower="-3.14" upper="3.14" effort="10" velocity="1"/>
    </joint>
    <link name="sph_link_y_2">
        <inertial>
            <mass value="0.001"/>
            <inertia ixx="4.000000000000001e-06" iyy="4.000000000000001e-06" izz="4.000000000000001e-06" ixy="0.0" ixz="0.0" iyz="0.0"/>
            <origin xyz="0 0 0" rpy="0 0 0"/>
        </inertial>
        <visual>
            <origin xyz="0 0 0" rpy="0 0 0"/>
            <geometry>
                <sphere radius="0.1"/>
            </geometry>
            <material name="cyan">
                <color rgba="0.0 1.0 1.0 1.0"/>
            </material>
        </visual>
    </link>
    <joint name="sph_joint_z_2" type="revolute">
        <parent link="sph_link_y_2"/>
        <child link="sph_link_z_2"/>
        <origin xyz="0 0 0" rpy="0 0 0"/>
        <axis xyz="0 0 1"/>
        <limit lower="-3.14" upper="3.14" effort="10" velocity="1"/>
    </joint>
    <link name="sph_link_z_2">
        <inertial>
            <mass value="0.001"/>
            <inertia ixx="4.000000000000001e-06" iyy="4.000000000000001e-06" izz="4.000000000000001e-06" ixy="0.0" ixz="0.0" iyz="0.0"/>
            <origin xyz="0 0 0" rpy="0 0 0"/>
        </inertial>
        <visual>
            <origin xyz="0 0 0" rpy="0 0 0"/>
            <geometry>
                <sphere radius="0.1"/>
            </geometry>
            <material name="cyan">
                <color rgba="0.0 1.0 1.0 1.0"/>
            </material>
        </visual>
    </link>
    <joint name="joint3" type="fixed">
        <parent link="sph_link_z_2"/>
        <child link="link3"/>
        <origin xyz="0 0 0" rpy="0 0 0"/>
    </joint>
    <link name="link3">
        <inertial>
            <mass value="1.0"/>
            <inertia ixx="0.0014583333333333334" iyy="0.0014583333333333334" izz="0.0012500000000000002" ixy="0.0" ixz="0.0" iyz="0.0"/>
            <origin xyz="0 0 0.05" rpy="0 0 0"/>
        </inertial>
        <visual>
            <origin xyz="0 0 0.05" rpy="0 0 0"/>
            <geometry>
                <cylinder length="0.1" radius="0.05"/>
            </geometry>
            <material name="cyan">
                <color rgba="0.0 1.0 1.0 1.0"/>
            </material>
        </visual>
        <collision>
            <origin xyz="0 0 0.05" rpy="0 0 0"/>
            <geometry>
                <cylinder length="0.1" radius="0.05"/>
            </geometry>
        </collision>
    </link>
    <joint name="probe_joint" type="fixed">
        <parent link="link3"/>
        <child link="probe_link"/>
        <origin xyz="0 0 0.1" rpy="0 0 0"/>
    </joint>
    <link name="probe_link">
        <inertial>
            <mass value="0.0"/>
            <inertia ixx="0.0" iyy="0.0" izz="0.0" ixy="0.0" ixz="0.0" iyz="0.0"/>
            <origin xyz="0 0 0" rpy="0 0 0"/>
        </inertial>
        <visual>
            <origin xyz="0 0 0" rpy="0 0 0"/>
            <geometry>
                <cylinder length="0.1" radius="0.01"/>
            </geometry>
            <material name="gray">
                <color rgba="0.5 0.5 0.5 1"/>
            </material>
        </visual>
    </link>
    <joint name="end_effector_joint" type="fixed">
        <parent link="probe_link"/>
        <child link="end_effector"/>
        <origin xyz="0 0 0.1" rpy="0 0 0"/>
    </joint>
    <link name="end_effector">
        <inertial>
            <mass value="0.0"/>
            <inertia ixx="0.0" iyy="0.0" izz="0.0" ixy="0.0" ixz="0.0" iyz="0.0"/>
            <origin xyz="0 0 0" rpy="0 0 0"/>
        </inertial>
        <visual>
            <origin xyz="0 0 0" rpy="0 0 0"/>
            <geometry>
                <cylinder length="0" radius="0"/>
            </geometry>
            <material name="gray">
                <color rgba="0.5 0.5 0.5 1"/>
            </material>
        </visual>
    </link>
</robot>
