<?xml version="1.0"?>
<robot name="prrr_manipulator">

  <!-- Base Link -->
  <link name="base_link">
    <visual>
      <origin xyz="0 0 0" rpy="0 0 0"/>
      <geometry>
        <box size="0.25 0.25 0.25"/>
      </geometry>
      <material name="gray">
        <color rgba="0.5 0.5 0.5 1"/>
      </material>
    </visual>
  </link>

  <!-- Joint -->
  <joint name="prismatic1" type="prismatic">
    <parent link="base_link"/>
    <child link="link1"/>
    <origin xyz="0 0 0.125" rpy="0 0 0"/>
    <axis xyz="0 1 0"/>
    <limit lower="-3.14" upper="3.14" effort="10" velocity="1"/>
  </joint>

  <!-- Link 1 -->
  <link name="link1">
  </link>

  <!-- Joint -->
  <joint name="revolute1" type="revolute">
    <parent link="link1"/>
    <child link="link2"/>
    <origin xyz="0 0 0" rpy="0 0 0"/>
    <axis xyz="1 0 0"/>
    <limit lower="-3.14" upper="3.14" effort="10" velocity="1"/>
  </joint>

  <!-- Link 2 -->
  <link name="link2">
    <visual>
      <origin xyz="0 0 0.5" rpy="0 0 0"/>
      <geometry>
        <cylinder length="1" radius="0.05"/>
      </geometry>
      <material name="blue">
        <color rgba="0 0 1 1"/>
      </material>
    </visual>
    <collision>
      <origin xyz="0 0 0.5" rpy="0 0 0"/>
      <geometry>
        <cylinder length="1" radius="0.05"/>
      </geometry>
    </collision>
  </link>

  <!-- Joint -->
  <joint name="revolute2" type="revolute">
    <parent link="link2"/>
    <child link="link3"/>
    <origin xyz="0 0 1" rpy="0 0 0"/>
    <axis xyz="1 0 0"/>
    <limit lower="-3.14" upper="3.14" effort="10" velocity="1"/>
  </joint>

  <!-- Link 2 -->
  <link name="link3">
    <visual>
      <origin xyz="0 0 0.5" rpy="0 0 0"/>
      <geometry>
        <cylinder length="1" radius="0.05"/>
      </geometry>
      <material name="green">
        <color rgba="0 1 0 1"/>
      </material>
    </visual>
    <collision>
      <origin xyz="0 0 0.5" rpy="0 0 0"/>
      <geometry>
        <cylinder length="1" radius="0.05"/>
      </geometry>
    </collision>
  </link>

  <!-- Joint -->
  <joint name="revolute3" type="revolute">
    <parent link="link3"/>
    <child link="link4"/>
    <origin xyz="0 0 1" rpy="0 0 0"/>
    <axis xyz="1 0 0"/>
    <limit lower="-3.14" upper="3.14" effort="10" velocity="1"/>
  </joint>

  <!-- Link 3 -->
  <link name="link4">
    <visual>
      <origin xyz="0 0 0.5" rpy="0 0 0"/>
      <geometry>
        <cylinder length="1" radius="0.05"/>
      </geometry>
      <material name="yellow">
        <color rgba="1 1 0 1"/>
      </material>
    </visual>
    <collision>
      <origin xyz="0 0 0.5" rpy="0 0 0"/>
      <geometry>
        <cylinder length="1" radius="0.05"/>
      </geometry>
    </collision>
  </link>

  <!-- Joint -->
  <joint name="fixed1" type="fixed">
    <parent link="link4"/>
    <child link="wrist"/>
    <origin xyz="0 0 1.025" rpy="0 0 0"/>
    <axis xyz="0 0 1"/>
    <limit lower="-3.14" upper="3.14" effort="10" velocity="1"/>
  </joint>

  <!-- Wrist Link -->
  <link name="wrist">
    <visual>
      <origin xyz="0 0 0" rpy="0 0 0"/>
      <geometry>
        <box size="0.05 0.25 0.05"/>
      </geometry>
      <material name="purple">
        <color rgba="0.5 0 0.5 1"/>
      </material>
    </visual>
    <collision>
      <origin xyz="0 0 0" rpy="0 0 0"/>
      <geometry>
        <box size="0.05 0.25 0.05"/>
      </geometry>
    </collision>
  </link>

  <!-- Joint -->
  <joint name="fixed2" type="fixed">
    <parent link="wrist"/>
    <child link="left_finger"/>
    <origin xyz="0 -0.1 0.075" rpy="0 0 0"/>
  </joint>

  <!-- Left Finger Link -->
  <link name="left_finger">
    <visual>
      <origin xyz="0 0 0" rpy="0 0 0"/>
      <geometry>
        <box size="0.05 0.05 0.15"/>
      </geometry>
      <material name="purple">
        <color rgba="0.5 0 0.5 1"/>
      </material>
    </visual>
    <collision>
      <origin xyz="0 0 0" rpy="0 0 0"/>
      <geometry>
        <box size="0.05 0.05 0.15"/>
      </geometry>
    </collision>
  </link>

  <!-- Joint -->
  <joint name="fixed3" type="fixed">
    <parent link="wrist"/>
    <child link="right_finger"/>
    <origin xyz="0 0.1 0.075" rpy="0 0 0"/>
  </joint>

  <!-- Right Finger Link -->
  <link name="right_finger">
    <visual>
      <origin xyz="0 0 0" rpy="0 0 0"/>
      <geometry>
        <box size="0.05 0.05 0.15"/>
      </geometry>
      <material name="purple">
        <color rgba="0.5 0 0.5 1"/>
      </material>
    </visual>
    <collision>
      <origin xyz="0 0 0" rpy="0 0 0"/>
      <geometry>
        <box size="0.05 0.05 0.15"/>
      </geometry>
    </collision>
  </link>

  <!-- Center of gripper -->
  <link name="gripper_center">
    <visual>
      <origin xyz="0 0 0.0" rpy="0 0 0"/>
      <geometry>
        <sphere radius="0.02"/> 
      </geometry>
      <material name="red">
        <color rgba="1 0 0 1"/>
      </material>
    </visual>
  </link>

  <!-- Joint -->
  <joint name="fixed4" type="fixed">
    <parent link="wrist"/>
    <child link="gripper_center"/>
    <origin xyz="0 0 0.15" rpy="0 0 0"/>
  </joint>  

</robot>
